Workbook

Sheet README
A1: NATO-area aviation resilience baseline
A2: Version | B2: Working baseline v0.1 — 23 September 2026
A3: Research question | B3: Does the rate, severity, or character of aviation information/infrastructure failures or non-hostile military aircraft losses during the Iran-war period depart from a longer historical baseline?
A4: Observation window | B4: 28 Feb 2026 – 23 Sep 2026
A5: Control design | B5: 2016–2019 pre-COVID; 2020–2021 COVID/low exposure; 2022–2025 post-COVID/Ukraine-war; 1 Jan–27 Feb 2026 immediate pre-war control.
A6: Core rule | B6: Do not infer a common cause from clustering. Civil ATM/infrastructure, GNSS/EW interference, military accidents, and VIP aviation-security events remain separate streams until evidence connects them.
A7: Civil scope | B7: EUROCONTROL Network Manager area / European ATM where official longitudinal data are available. This is not identical to NATO membership and is retained as a regional control series.
A8: Military scope | B8: NATO-member military aircraft: non-hostile losses/serious accidents. Event-level historical backfill remains a separate workstream because no single NATO-wide public series has yet been identified.
A9: Cause coding | B9: confirmed digital/IT; confirmed electrical; GNSS/EW; mechanical/physical; collision; hostile fire; friendly fire; unresolved; no evidence of digital involvement.
A10: Interpretation warning | B10: Raw annual counts are not comparable without exposure. COVID years are flagged and flight-normalised metrics should be preferred where available.
A12: New causal layer | B12: Causal_Taxonomy defines exactly what 'why' means; Causal_Event_Ledger records proximate cause, resilience failure, confidence, digital relevance, war/EW relevance, and explanation status.
A13: Critical distinction | B13: 'No public evidence of digital involvement' is NOT the same as 'digital involvement ruled out'.
A14: Interpretation | B14: The ledger must be backfilled under identical inclusion rules before annual proportions are treated as comparative statistics.
... A34: Military limitation | B34: The UK 2026 military accidents remain too unresolved/recent for mechanism matching; compare investigation maturity now and mechanism later.

Sheet Civil_Annual_Baseline
A1: Year | B1: Regime | C1: Flights_millions | D1: Traffic_value_status | E1: Enroute_ATFM_min_per_flight | F1: Airport_ATFM_min_per_flight | G1: Total_ATFM_min_per_flight | H1: Context / caveat | I1: Primary source URL
A2: 2016 | B2: Pre-COVID | C2: 10.163 | D2: approx from official avg daily traffic | E2: 0.86 | F2: 0.67 | G2: 1.53 | H2: High-traffic pre-COVID control. Official report records multiple radar, frequency, VOR, ILS and radio-navigation disruptions. | I2: https://www.eurocontrol.int/sites/default/files/publication/files/nm-annual-network-operations-report-2016-main-report.pdf
A3: 2017 | B3: Pre-COVID | C3: 10.606 | D3: approx from official avg daily traffic | E3: 0.88 | F3: 0.62 | G3: 1.5 | H3: High-traffic pre-COVID control. | I3: https://www.eurocontrol.int/publication/annual-network-operations-report-2017
A4: 2018 | B4: Pre-COVID | C4: 11.011 | D4: approx from official avg daily traffic | E4: 1.73 | F4: 0.6 | G4: 2.33 | H4: Severe network-delay year; useful noisy-year control. Included major Network Manager technical outage. | I4: https://www.eurocontrol.int/publication/annual-network-operations-report-2018
A5: 2019 | B5: Pre-COVID | C5: 11.106 | D5: approx from official avg daily traffic | E5: 1.57 | F5: 0.6 | G5: 2.17 | H5: Pre-pandemic traffic peak; EUROCONTROL described 2019 delay as third-worst of prior decade despite improvement vs 2018. | I5: https://www.eurocontrol.int/publication/annual-network-operations-report-2019
A6: 2020 | B6: COVID | C6: 4.971 | D6: approx from official avg daily traffic | E6: 0.33 | F6: 0.2 | G6: 0.53 | H6: COVID exposure collapse. EUROCONTROL cautions against in-depth comparison with previous years. | I6: https://www.eurocontrol.int/publication/annual-network-operations-report-2020
A7: 2021 | B7: COVID | C7: 6.2 | D7: official annual figure | E7: 0.29 | F7: 0.18 | G7: 0.47 | H7: 56% of 2019 traffic; recovery year. | I7: https://www.eurocontrol.int/publication/annual-network-operations-report-2021
A8: 2022 | B8: Post-COVID / Ukraine war | C8: 9.3 | D8: official annual figure | E8: 1.8 | F8: 0.4 | G8: 2.2 | H8: Ukraine airspace closure and increased military operations explicitly identified as network challenges. | I8: https://www.eurocontrol.int/publication/annual-network-operations-report-2022
A9: 2023 | B9: Post-COVID / Ukraine war | C9: 10.2 | D9: official annual figure | E9: 1.8 | H9: Ukraine closure, increased military operations, weather and Middle East instability affected network. | I9: https://www.eurocontrol.int/publication/annual-network-operations-report-2023
A10: 2024 | B10: Post-COVID / Ukraine war | C10: 10.66 | D10: derived from 2025 11.1m being +4.1% YoY | E10: 2.13 | H10: En-route ATFM delay reached worst level since 2001; increased military training/exercise requirements also noted. | I10: https://www.eurocontrol.int/publication/annual-network-operations-report-2024
A11: 2025 | B11: Post-COVID / Ukraine war | C11: 11.1 | D11: official annual figure | E11: 1.66 | H11: Performance improved vs 2024/2023 despite traffic growth; Middle East instability and increased military airspace requirements noted. | I11: https://www.eurocontrol.int/publication/annual-network-operations-report-2025

Sheet Official_Disruption_Examples
A1: Date | B1: Year | C1: Location | D1: System/event | E1: Official impact | F1: Classification | G1: Why retained | H1: Source URL
A2: 2016-01-18 | B2: 2016 | C2: Frankfurt/Main | D2: VOR unserviceability | E2: 2,452 ATFM delay min | F2: radio-navigation | G2: Historical technical-failure comparator | H2: https://www.eurocontrol.int/sites/default/files/publication/files/nm-annual-network-operations-report-2016-main-report.pdf
A3: 2016-01-21 | B3: 2016 | C3: Istanbul airports | D3: Radar and frequency problems | E3: 12,656 ATFM delay min | F3: surveillance/comms | G3: Historical technical-failure comparator | H3: https://www.eurocontrol.int/sites/default/files/publication/files/nm-annual-network-operations-report-2016-main-report.pdf
A4: 2016-02-04 | B4: 2016 | C4: Frankfurt/Main | D4: ILS unserviceability | E4: 1,295 ATFM delay min | F4: navigation/landing aid | G4: Historical technical-failure comparator | H4: https://www.eurocontrol.int/sites/default/files/publication/files/nm-annual-network-operations-report-2016-main-report.pdf
A5: 2016-02-20 | B5: 2016 | C5: Zurich | D5: Radio-navigation / direction-finder problems | E5: 1,024 ATFM delay min | F5: radio-navigation | G5: Historical technical-failure comparator | H5: https://www.eurocontrol.int/sites/default/files/publication/files/nm-annual-network-operations-report-2016-main-report.pdf
A6: 2018-04-03 | B6: 2018 | C6: EUROCONTROL Network Manager | D6: Network Manager technical-system outage | E6: Contingency plan; precautionary capacity/departure-rate reductions | F6: central ATM technical system | G6: Large historical system-outage comparator | H6: https://www.eurocontrol.int/publication/annual-network-operations-report-2018
A7: 2024-07 | B7: 2024 | C7: EUROCONTROL network | D7: High en-route ATFM delay month | E7: 6,940,504 ATFM delay min; 6.5 min/flight total | F7: network performance | G7: Shows severe non-2026 operational month; not itself a technical outage | H7: https://www.eurocontrol.int/press-release/july-2024-overview-network-performance

Sheet 2026_Comparison_Framework
A1: Period | B1: Start | C1: End | D1: Role | E1: Civil ATM / infrastructure | F1: GNSS/EW | G1: Military non-hostile | H1: VIP aviation | I1: Status
A2: Immediate pre-war control | B2: 2026-01-01 | C2: 2026-02-27 | D2: Internal control | E2: Backfill required | F2: Backfill required | G2: Backfill required | H2: Backfill required | I2: OPEN
A3: Iran-war observation | B3: 2026-02-28 | C3: 2026-09-23 | D3: Observation | E3: Event dataset exists; official-stat backfill in progress | F3: Documented interference environment; quantify separately | G3: Event dataset exists; historical denominator/backfill required | H3: Event dataset exists | I3: IN PROGRESS

Sheet Source_Register
A1: Source family | B1: Coverage | C1: Use | D1: Official URL
A2: EUROCONTROL Annual Network Operations Reports | B2: 2016–2025 | C2: Traffic exposure; ATFM delay; network disruptions; ACC/airport technical events | D2: https://www.eurocontrol.int/network-performance
A3: EUROCONTROL Performance Review Reports | B3: Longitudinal | C3: En-route ATFM performance and historical comparison | D3: https://www.eurocontrol.int/publication/performance-review-report-prr-2025
A4: EUROCONTROL CODA / All-causes delay | B4: Annual | C4: Passenger-facing delay/cancellation context | D4: https://www.eurocontrol.int/publication/all-causes-delays-air-transport-europe-annual-2024
A5: EASA Annual Safety Review | B5: Annual / 10-year comparisons | C5: ATM/ANS safety occurrence and system-component-failure context | D5: https://www.easa.europa.eu/en/publication-types/annual-safety-review
A6: National military safety / service inquiries | B6: Event-level | C6: Military accident cause and investigation outcome | D6: To be populated per NATO member

Sheet Backfill_Queue
A1: Priority | B1: Workstream | C1: Task | D1: Why needed | E1: Status
A2: P0 | B2: 2026 civil | C2: Extract Jan–27 Feb and 28 Feb–23 Sep 2026 official EUROCONTROL monthly/weekly technical-disruption metrics | D2: Creates same-year before/after comparison | E2: OPEN
A3: P0 | B3: Military | C3: Build 2016–2025 NATO-member non-hostile military aircraft loss/serious-accident series from national official investigators | D3: Tests whether 2026 military-loss count is abnormal | E3: IN PROGRESS
A4: P0 | B4: Military | C4: Add flying-hours / sortie exposure where official national data permit | D4: Raw crash counts otherwise confounded by activity | E4: OPEN
A5: P1 | B5: Civil technical | C5: Extract annual event-level equipment/technical disruptions from EUROCONTROL reports 2016–2025 | D5: Tests severity and character, not just generic delay | E5: IN PROGRESS
A6: P1 | B6: GNSS/EW | C6: Build annual interference series and geography separately | D6: Prevents conflating known interference environment with accident causation | E6: OPEN
A7: P1 | B7: EASA | C7: Extract ATM/ANS serious incidents and system-component-failure series consistently | D7: Independent safety outcome check | E7: OPEN
A8: P2 | B8: VIP | C8: Backfill significant NATO VIP aviation-safety/security events with identical threshold | D8: Contextual stream; likely sparse | E8: OPEN

Sheet Causal_Taxonomy
A1: Causal code | B1: Definition | C1: Digital relevance default | D1: Use rule
A2: software_failure | B2: Software defect, crash, timing/race condition, corrupted processing | C2: confirmed causal | D2: Only where source identifies software
A3: network_connectivity | B3: Internal network/data connectivity failure | C3: confirmed causal | D3: Network path/connectivity explicitly identified
A4: power_failure | B4: Primary electrical supply failure | C4: not inherently digital | D4: Keep backup behaviour separately
A5: backup_failure | B5: Redundancy/backup system failed when demanded | C5: resilience failure | D5: Secondary cause / resilience field
A6: hardware_failure | B6: Identified physical computing/ATM equipment failure | C6: possible/confirmed | D6: Do not collapse into software
A7: comms_failure | B7: Voice/radio/data communications failure | C7: information-system relevant | D7: Specify voice/radio/datalink where known
A8: surveillance_failure | B8: Radar/ADS-B/surveillance degradation | C8: information-system relevant | D8: Specify sensor/system where known
A9: flight_data_processing | B9: Flight-plan/trajectory processing failure | C9: confirmed causal | D9: ATM processing layer
A10: datalink_cpdlc | B10: Controller–pilot datalink failure | C10: confirmed causal | D10: CPDLC/datalink only
A11: gnss_jamming | B11: Intentional denial/degradation of GNSS | C11: confirmed EW if established | D11: Do not infer from navigation anomaly alone
A12: gnss_spoofing | B12: Counterfeit GNSS signals causing false PNT | C12: confirmed EW if established | D12: Do not infer from navigation anomaly alone
... A26: unknown_no_public_explanation | B26: No adequate public causal account found | C26: unknown | D26: Use only after reasonable source search

Sheet Causal_Event_Ledger
A1: Date | B1: Period | C1: Country/region | D1: Stream | E1: Operator/system | F1: Event | G1: Proximate cause | H1: Secondary/resilience cause | I1: Mechanism/detail | J1: Cause confidence | K1: Digital relevance | L1: War/EW relevance | M1: Hostile action | N1: Public explanation status | O1: Impact/severity | P1: Why this row matters | Q1: Primary source URL | R1: Notes / next check
A2: 2016-01-18 | B2: Pre-COVID baseline | C2: Germany | D2: civil ATM/infrastructure | E2: Frankfurt/Main | F2: VOR unserviceability | G2: hardware_failure | I2: VOR/navigation aid unavailable | J2: official reported | K2: information-system relevant | L2: none demonstrated | M2: no | N2: explained at system level | O2: 2,452 ATFM delay min | P2: Historical navigation-system failure comparator | Q2: https://www.eurocontrol.int/sites/default/files/publication/files/nm-annual-network-operations-report-2016-main-report.pdf | R2: Underlying component root cause not extracted yet
A3: 2016-01-21 | B3: Pre-COVID baseline | C3: Türkiye | D3: civil ATM/infrastructure | E3: Istanbul airports | F3: Radar and frequency problems | G3: surveillance_failure | H3: comms_failure | I3: Radar plus frequency problems | J3: official reported | K3: information-system relevant | L3: none demonstrated | M3: no | N3: explained at system level | O3: 12,656 ATFM delay min | P3: Large pre-war surveillance/comms comparator | Q3: https://www.eurocontrol.int/sites/default/files/publication/files/nm-annual-network-operations-report-2016-main-report.pdf
A4: 2016-02-04 | B4: Pre-COVID baseline | C4: Germany | D4: civil ATM/infrastructure | E4: Frankfurt/Main | F4: ILS unserviceability | G4: hardware_failure | I4: Instrument landing system unavailable | J4: official reported | K4: information-system relevant | L4: none demonstrated | M4: no | N4: explained at system level | O4: 1,295 ATFM delay min | P4: Historical landing/navigation failure comparator | Q4: https://www.eurocontrol.int/sites/default/files/publication/files/nm-annual-network-operations-report-2016-main-report.pdf
A5: 2016-02-20 | B5: Pre-COVID baseline | C5: Switzerland | D5: civil ATM/infrastructure | E5: Zurich | F5: Radio-navigation / direction-finder problems | G5: hardware_failure | I5: Radio-navigation equipment problem | J5: official reported | K5: information-system relevant | L5: none demonstrated | M5: no | N5: explained at system level | O5: 1,024 ATFM delay min | P5: Historical radio-navigation comparator | Q5: https://www.eurocontrol.int/sites/default/files/publication/files/nm-annual-network-operations-report-2016-main-report.pdf
A6: 2018-04-03 | B6: Pre-COVID baseline | C6: EUROCONTROL area | D6: civil ATM/infrastructure | E6: Network Manager | F6: Central technical-system outage | G6: hardware_failure | I6: NM technical system unavailable; contingency capacity reductions | J6: official reported | K6: information-system relevant | L6: none demonstrated | M6: no | N6: explained at system level | O6: Network-wide contingency measures | P6: Major pre-2026 central-system outage comparator | Q6: https://www.eurocontrol.int/publication/annual-network-operations-report-2018 | R6: Need deeper report extraction for exact root cause
A7: 2024-07-19 | B7: Post-COVID / Ukraine-war baseline | C7: Europe/US | D7: civil airline/airport IT | E7: Multiple carriers/airports | F7: CrowdStrike/Microsoft-related disruption | G7: software_failure | I7: Cloud-based systems used by carriers affected; passenger booking/check-in impacted | J7: confirmed external technical event | K7: confirmed causal | L7: none demonstrated | M7: no | N7: explained | O7: Widespread carrier/airport disruption | P7: Excellent non-war-period mass digital-failure comparator | Q7: https://www.eurocontrol.int/sites/default/files/2025-05/eurocontrol-annual-network-operations-report-2024.pdf | R7: Do not treat as ATM failure; airline/airport IT layer
A8: 2026-03-25 | B8: Iran-war observation | C8: Europe | D8: GNSS/EW environment | E8: EASA/EUROCONTROL | F8: Joint GNSS interference action plan | G8: gnss_jamming | I8: Interference regular near conflict zones; safety/resilience threat | J8: official assessment | K8: confirmed environmental | L8: documented wartime EW environment | M8: not an accident | N8: publicly acknowledged threat | O8: European action plan launched | P8: Marks official recognition of wartime PNT threat | Q8: https://www.easa.europa.eu/en/newsroom-and-events/press-releases/easa-and-eurocontrol-publish-joint-action-plan-ensure-safe | R8: Environmental row, not causal attribution to a crash
A9: 2026-07-03 | B9: Iran-war observation | C9: Europe/neighbouring airspace | D9: GNSS/EW environment | E9: EASA | F9: GNSS SIB Revision 4 | G9: gnss_jamming | H9: gnss_spoofing | I9: Recent jamming/spoofing occurrences prompted new mitigations | J9: official assessment | K9: confirmed environmental | L9: documented wartime/conflict-zone relevance | M9: not an accident | N9: publicly acknowledged threat | O9: Operational/training/ATC mitigations | P9: Shows interference severity/sophistication is independently documented | Q9: https://www.easa.europa.eu/en/newsroom-and-events/news/easa-updates-safety-information-bulletin-gnss-interference
A10: 2026-09-17 | B10: Iran-war observation | C10: NATO/European FIRs | D10: GNSS/EW environment | E10: EASA monitoring | F10: Multiple FIRs affected by GNSS interference | G10: gnss_jamming | H10: gnss_spoofing | I10: Affected FIR list includes Ankara, Istanbul, Bucharest, Sofia, Warsaw, Tallinn, Helsinki, Riga, Vilnius | J10: official monitoring | K10: confirmed environmental | L10: documented conflict-zone-linked interference | M10: not an accident | N10: publicly acknowledged threat | O10: Multi-country information environment | P10: Provides geographic overlap without proving incident causation | Q10: https://www.easa.europa.eu/en/domains/air-operations/global-navigation-satellite-system-outages-and-alterations | R10: Snapshot dated 17 Sep 2026
A11: 2023-06-03 | B11: Post-COVID / Ukraine-war baseline | C11: Germany | D11: civil ATM/infrastructure | E11: München ACC | F11: ICAS2 ATM-system transition | G11: flight_data_processing | I11: Transition to new ATM system ICAS2 | J11: official reported | K11: information-system relevant | L11: none demonstrated | M11: no | N11: explained at system level | O11: 111,766 ATFM delay min | P11: Large software/system-change comparator | Q11: https://www.eurocontrol.int/sites/default/files/2023-07/eurocontrol-nm-monthly-network-operations-report-june-2023.pdf | R11: Not necessarily a fault: retained as system-transition disruption
A12: 2023-06-01 | B12: Post-COVID / Ukraine-war baseline | C12: France | D12: civil ATM/infrastructure | E12: Paris ACC | F12: New FDPS implementation | G12: flight_data_processing | I12: Implementation of new flight-data-processing system | J12: official reported | K12: information-system relevant | L12: none demonstrated | M12: no | N12: explained at system level | O12: 19,986 ATFM delay min during month | P12: Shows major disruption can arise from planned digital-system change | Q12: https://www.eurocontrol.int/sites/default/files/2023-07/eurocontrol-nm-monthly-network-operations-report-june-2023.pdf | R12: Date coded to month start because report gives monthly total
A13: 2023-06-03 | B13: Post-COVID / Ukraine-war baseline | C13: Greece | D13: civil ATM/infrastructure | E13: Athens ACC | F13: Radar issues | G13: surveillance_failure | I13: Radar issues on 3 and 11 June | J13: official reported | K13: information-system relevant | L13: none demonstrated | M13: no | N13: explained at system level | O13: 4,496 ATFM delay min | P13: Direct surveillance-system comparator | Q13: https://www.eurocontrol.int/sites/default/files/2023-07/eurocontrol-nm-monthly-network-operations-report-june-2023.pdf
A14: 2023-06-14 | B14: Post-COVID / Ukraine-war baseline | C14: United Kingdom | D14: civil ATM/infrastructure | E14: London ACC | F14: Computer system failure | G14: hardware_failure | I14: Computer system failure | J14: official reported | K14: information-system relevant | L14: none demonstrated | M14: no | N14: explained at system level | O14: 12,450 ATFM delay min | P14: Very useful pre-2026 UK digital-system comparator | Q14: https://www.eurocontrol.int/sites/default/files/2023-07/eurocontrol-nm-monthly-network-operations-report-june-2023.pdf | R14: Root component not specified in monthly report
A15: 2023-06-15 | B15: Post-COVID / Ukraine-war baseline | C15: Spain | D15: civil ATM/infrastructure | E15: Palma de Mallorca | F15: ATC equipment issues | G15: hardware_failure | I15: ATC equipment issues on 15 and 30 June | J15: official reported | K15: information-system relevant | L15: none demonstrated | M15: no | N15: explained at system level | O15: 1,596 ATFM delay min | P15: Airport ATC-equipment comparator | Q15: https://www.eurocontrol.int/sites/default/files/2023-07/eurocontrol-nm-monthly-network-operations-report-june-2023.pdf
A16: 2023-06-24 | B16: Post-COVID / Ukraine-war baseline | C16: France | D16: civil ATM/infrastructure | E16: Reims ACC | F16: IT services failure | G16: network_connectivity | I16: IT services failure | J16: official reported | K16: confirmed causal | L16: none demonstrated | M16: no | N16: explained at system level | O16: 3,631 ATFM delay min | P16: Explicit IT-services failure comparator | Q16: https://www.eurocontrol.int/sites/default/files/2023-07/eurocontrol-nm-monthly-network-operations-report-june-2023.pdf
A17: 2023-06-30 | B17: Post-COVID / Ukraine-war baseline | C17: Spain | D17: civil ATM/infrastructure | E17: Barcelona ACC | F17: FDPS failure | G17: flight_data_processing | I17: Flight-data-processing-system failure | J17: official reported | K17: confirmed causal | L17: none demonstrated | M17: no | N17: explained at system level | O17: 6,909 ATFM delay min | P17: Explicit flight-data-processing failure comparator | Q17: https://www.eurocontrol.int/sites/default/files/2023-07/eurocontrol-nm-monthly-network-operations-report-june-2023.pdf
A18: 2023-06-30 | B18: Post-COVID / Ukraine-war baseline | C18: Spain | D18: civil ATM/infrastructure | E18: Ibiza airport | F18: ATC equipment failure | G18: hardware_failure | I18: ATC equipment failure | J18: official reported | K18: information-system relevant | L18: none demonstrated | M18: no | N18: explained at system level | O18: 2,278 ATFM delay min | P18: Airport equipment-failure comparator | Q18: https://www.eurocontrol.int/sites/default/files/2023-07/eurocontrol-nm-monthly-network-operations-report-june-2023.pdf
A19: 2023-06-01 | B19: Post-COVID / Ukraine-war baseline | C19: Greece | D19: civil ATM/infrastructure | E19: Athens airport | F19: Radar issues | G19: surveillance_failure | I19: Radar issues throughout June | J19: official reported | K19: information-system relevant | L19: none demonstrated | M19: no | N19: explained at system level | O19: 56,728 ATFM delay min | P19: Large sustained surveillance degradation comparator | Q19: https://www.eurocontrol.int/sites/default/files/2023-07/eurocontrol-nm-monthly-network-operations-report-june-2023.pdf | R19: Month-level event
A20: 2024-08-01 | B20: Post-COVID / Ukraine-war baseline | C20: France | D20: civil ATM/infrastructure | E20: Brest ACC | F20: ATC frequency issues | G20: comms_failure | I20: Frequency issues throughout August | J20: official reported | K20: information-system relevant | L20: none demonstrated | M20: no | N20: explained at system level | O20: 25,499 ATFM delay min | P20: Large sustained communications comparator | Q20: https://www.eurocontrol.int/sites/default/files/2025-05/eurocontrol-annual-network-operations-report-2024.pdf
A21: 2024-08-10 | B21: Post-COVID / Ukraine-war baseline | C21: France/Germany/Netherlands/Austria | D21: civil ATM/infrastructure | E21: Reims/Bordeaux/Maastricht/Vienna | F21: CPDLC issue | G21: datalink_cpdlc | I21: CPDLC issue limited capacity in several ACCs | J21: official reported | K21: confirmed causal | L21: none demonstrated | M21: no | N21: explained at system level | O21: 3,813 ATFM delay min across listed centres | P21: Networked datalink failure across multiple ACCs | Q21: https://www.eurocontrol.int/sites/default/files/2025-05/eurocontrol-annual-network-operations-report-2024.pdf | R21: Sum of Reims 1,727; Bordeaux 409; Maastricht 1,108; Vienna 569
A22: 2024-08-16 | B22: Post-COVID / Ukraine-war baseline | C22: Norway | D22: civil ATM/infrastructure | E22: Bodø | F22: Power failure | G22: power_failure | I22: Power failure 16–17 August | J22: official reported | K22: not applicable | L22: none demonstrated | M22: no | N22: explained at system level | O22: 6,097 ATFM delay min | P22: Physical infrastructure comparator | Q22: https://www.eurocontrol.int/sites/default/files/2025-05/eurocontrol-annual-network-operations-report-2024.pdf
A23: 2024-09-01 | B23: Post-COVID / Ukraine-war baseline | C23: France | D23: civil ATM/infrastructure | E23: Reims ACC | F23: Data link issue | G23: datalink_cpdlc | I23: Data link issue | J23: official reported | K23: confirmed causal | L23: none demonstrated | M23: no | N23: explained at system level | O23: 4,870 ATFM delay min | P23: Datalink comparator | Q23: https://www.eurocontrol.int/sites/default/files/2025-05/eurocontrol-annual-network-operations-report-2024.pdf
A24: 2024-09-07 | B24: Post-COVID / Ukraine-war baseline | C24: North Atlantic/UK-Ireland service | D24: civil ATM/infrastructure | E24: Shanwick OACC | F24: Oceanic Centre technical issue | G24: hardware_failure | I24: Technical issue with Oceanic Centre systems | J24: official reported | K24: information-system relevant | L24: none demonstrated | M24: no | N24: explained at system level | O24: 1,321 ATFM delay min | P24: Oceanic-control-system comparator | Q24: https://www.eurocontrol.int/sites/default/files/2025-05/eurocontrol-annual-network-operations-report-2024.pdf
A25: 2024-09-23 | B25: Post-COVID / Ukraine-war baseline | C25: Croatia | D25: civil ATM/infrastructure | E25: Zagreb ACC | F25: Communication system failure | G25: comms_failure | I25: Communication system failure | J25: official reported | K25: confirmed causal | L25: none demonstrated | M25: no | N25: explained at system level | O25: 1,113 ATFM delay min | P25: Explicit communications-system failure | Q25: https://www.eurocontrol.int/sites/default/files/2025-05/eurocontrol-annual-network-operations-report-2024.pdf
A26: 2024-09-24 | B26: Post-COVID / Ukraine-war baseline | C26: France | D26: civil ATM/infrastructure | E26: Marseille ACC | F26: Communication system failure | G26: comms_failure | I26: Failure caused precautionary measures in neighbouring ACCs | J26: official reported | K26: confirmed causal | L26: none demonstrated | M26: no | N26: explained at system level | O26: 6,888 min Marseille + 4,245 neighbouring delay | P26: Large communications failure with cross-border propagation | Q26: https://www.eurocontrol.int/sites/default/files/2025-05/eurocontrol-annual-network-operations-report-2024.pdf | R26: Neighbouring: Alger 1,492; Barcelona 1,345; Madrid 1,408
A27: 2024-10-04 | B27: Post-COVID / Ukraine-war baseline | C27: Germany | D27: civil ATM/infrastructure | E27: Karlsruhe UAC / Munich / Bremen | F27: DFS control-centre technical issue | G27: hardware_failure | I27: Technical issue led to capacity reduction across several German centres | J27: official reported | K27: information-system relevant | L27: none demonstrated | M27: no | N27: explained at system level | O27: 42,161 ATFM delay min | P27: Very large multi-centre technical-failure comparator | Q27: https://www.eurocontrol.int/sites/default/files/2025-05/eurocontrol-annual-network-operations-report-2024.pdf
A28: 2024-10-04 | B28: Post-COVID / Ukraine-war baseline | C28: Germany | D28: civil ATM/infrastructure | E28: Bremen | F28: Communication system issue | G28: comms_failure | I28: Issues on 4 and 15 October | J28: official reported | K28: information-system relevant | L28: none demonstrated | M28: no | N28: explained at system level | O28: 2,266 ATFM delay min | P28: Communications comparator | Q28: https://www.eurocontrol.int/sites/default/files/2025-05/eurocontrol-annual-network-operations-report-2024.pdf
A29: 2024-10-20 | B29: Post-COVID / Ukraine-war baseline | C29: Italy | D29: civil ATM/infrastructure | E29: Milano | F29: FDPS failure | G29: flight_data_processing | I29: Flight-data-processing-system failure | J29: official reported | K29: confirmed causal | L29: none demonstrated | M29: no | N29: explained at system level | O29: 9,772 ATFM delay min | P29: Explicit FDPS comparator | Q29: https://www.eurocontrol.int/sites/default/files/2025-05/eurocontrol-annual-network-operations-report-2024.pdf
A30: 2024-11-22 | B30: Post-COVID / Ukraine-war baseline | C30: Germany | D30: civil ATM/infrastructure | E30: Karlsruhe UAC | F30: FDPS instability | G30: flight_data_processing | I30: Flight-data-processing-system instability | J30: official reported | K30: confirmed causal | L30: none demonstrated | M30: no | N30: explained at system level | O30: 4,152 ATFM delay min | P30: Digital instability rather than complete outage | Q30: https://www.eurocontrol.int/sites/default/files/2025-05/eurocontrol-annual-network-operations-report-2024.pdf
A31: 2024-11-23 | B31: Post-COVID / Ukraine-war baseline | C31: Netherlands/France | D31: civil ATM/infrastructure | E31: Maastricht UAC / Bordeaux | F31: Datalink system issues | G31: datalink_cpdlc | I31: Datalink system issues | J31: official reported | K31: confirmed causal | L31: none demonstrated | M31: no | N31: explained at system level | O31: 1,523 ATFM delay min | P31: Networked datalink comparator | Q31: https://www.eurocontrol.int/sites/default/files/2025-05/eurocontrol-annual-network-operations-report-2024.pdf
A32: 2024-12-01 | B32: Post-COVID / Ukraine-war baseline | C32: Spain | D32: civil ATM/infrastructure | E32: Barcelona / Valencia TMA | F32: Local radar issues | G32: surveillance_failure | I32: Local radar issues throughout December | J32: official reported | K32: information-system relevant | L32: none demonstrated | M32: no | N32: explained at system level | O32: 11,537 ATFM delay min | P32: Sustained radar-degradation comparator | Q32: https://www.eurocontrol.int/sites/default/files/2025-05/eurocontrol-annual-network-operations-report-2024.pdf | R32: Month-level event
A33: 2025-06-01 | B33: Post-COVID / Ukraine-war baseline | C33: Europe | D33: civil ATM/infrastructure | E33: European datalink network | F33: CPDLC service degradation | G33: datalink_cpdlc | I33: About 66 hours of flight delay attributed to CPDLC issues in summer comparison | J33: official reported | K33: confirmed causal | L33: none demonstrated | M33: no | N33: explained at system level | O33: ~66 delay hours vs ~500 hours same period 2024 | P33: Quantifies improvement after 2024 datalink resilience work | Q33: https://www.eurocontrol.int/sites/default/files/2025-08/eurocontrol-datalink-summer-performance-report-2025.pdf | R33: Period-level metric rather than one outage
A34: 2025-08-01 | B34: Post-COVID / Ukraine-war baseline | C34: Europe | D34: civil ATM/infrastructure | E34: European datalink network | F34: CPDLC performance | G34: datalink_cpdlc | I34: 57.6 delay hours vs 195.9 hours Aug 2024 despite >20% CPDLC traffic growth | J34: official reported | K34: confirmed causal | L34: none demonstrated | M34: no | N34: explained at system level | O34: 57.6 delay hours | P34: Strong exposure-aware resilience comparator | Q34: https://www.eurocontrol.int/publication/datalink-summer-performance-report-august-2025 | R34: Provider Abort rate 8.6 per 100 hours remained stable

Sheet Causal_Summary
A1: Current causal coding — working snapshot
A2: Metric | B2: Current ledger count
A3: Rows in causal ledger | B3: =COUNTA(Causal_Event_Ledger!A2:A500)
A4: Rows with confirmed environmental GNSS/EW | B4: =COUNTIF(Causal_Event_Ledger!K2:K500,"confirmed environmental")
A5: Rows information-system relevant | B5: =COUNTIF(Causal_Event_Ledger!K2:K500,"information-system relevant")
A6: Rows confirmed causal digital | B6: =COUNTIF(Causal_Event_Ledger!K2:K500,"confirmed causal")
A7: Unknown / no evidence rows | B7: =COUNTIF(Causal_Event_Ledger!K2:K500,"unknown")+COUNTIF(Causal_Event_Ledger!K2:K500,"no evidence either way")
A8: Important | B8: This sheet is descriptive of the backfilled ledger, not a claim about population rates until all years are populated.

Sheet Why_By_Year
A1: Year | B1: comms_failure | C1: surveillance_failure | D1: flight_data_processing | E1: datalink_cpdlc | F1: network_connectivity | G1: power_failure | H1: hardware_failure | I1: software_failure | J1: gnss_jamming | K1: gnss_spoofing | L1: unknown_investigation | M1: Ledger rows
A2: 2016 | B2: =COUNTIFS(Causal_Event_Ledger!$A$2:$A$500,">="&"2016-01-01",Causal_Event_Ledger!$A$2:$A$500,"<="&"2016-12-31",Causal_Event_Ledger!$G$2:$G$500,"comms_failure")+COUNTIFS(Causal_Event_Ledger!$A$2:$A$500,">="&"2016-01-01",Causal_Event_Ledger!$A$2:$A$500,"<="&"2016-12-31",Causal_Event_Ledger!$H$2:$H$500,"comms_failure") | C2: =COUNTIFS(Causal_Event_Ledger!$A$2:$A$500,">="&"2016-01-01",Causal_Event_Ledger!$A$2:$A$500,"<="&"2016-12-31",Causal_Event_Ledger!$G$2:$G$500,"surveillance_failure")+COUNTIFS(Causal_Event_Ledger!$A$2:$A$500,">="&"2016-01-01",Causal_Event_Ledger!$A$2:$A$500,"<="&"2016-12-31",Causal_Event_Ledger!$H$2:$H$500,"surveillance_failure") | D2: =COUNTIFS(Causal_Event_Ledger!$A$2:$A$500,">="&"2016-01-01",Causal_Event_Ledger!$A$2:$A$500,"<="&"2016-12-31",Causal_Event_Ledger!$G$2:$G$500,"flight_data_processing")+COUNTIFS(Causal_Event_Ledger!$A$2:$A$500,">="&"2016-01-01",Causal_Event_Ledger!$A$2:$A$500,"<="&"2016-12-31",Causal_Event_Ledger!$H$2:$H$500,"flight_data_processing") | E2: =COUNTIFS(Causal_Event_Ledger!$A$2:$A$500,">="&"2016-01-01",Causal_Event_Ledger!$A$2:$A$500,"<="&"2016-12-31",Causal_Event_Ledger!$G$2:$G$500,"datalink_cpdlc")+COUNTIFS(Causal_Event_Ledger!$A$2:$A$500,">="&"2016-01-01",Causal_Event_Ledger!$A$2:$A$500,"<="&"2016-12-31",Causal_Event_Ledger!$H$2:$H$500,"datalink_cpdlc") | F2: =COUNTIFS(Causal_Event_Ledger!$A$2:$A$500,">="&"2016-01-01",Causal_Event_Ledger!$A$2:$A$500,"<="&"2016-12-31",Causal_Event_Ledger!$G$2:$G$500,"network_connectivity")+COUNTIFS(Causal_Event_Ledger!$A$2:$A$500,">="&"2016-01-01",Causal_Event_Ledger!$A$2:$A$500,"<="&"2016-12-31",Causal_Event_Ledger!$H$2:$H$500,"network_connectivity") | G2: =COUNTIFS(Causal_Event_Ledger!$A$2:$A$500,">="&"2016-01-01",Causal_Event_Ledger!$A$2:$A$500,"<="&"2016-12-31",Causal_Event_Ledger!$G$2:$G$500,"power_failure")+COUNTIFS(Causal_Event_Ledger!$A$2:$A$500,">="&"2016-01-01",Causal_Event_Ledger!$A$2:$A$500,"<="&"2016-12-31",Causal_Event_Ledger!$H$2:$H$500,"power_failure") | H2: =COUNTIFS(Causal_Event_Ledger!$A$2:$A$500,">="&"2016-01-01",Causal_Event_Ledger!$A$2:$A$500,"<="&"2016-12-31",Causal_Event_Ledger!$G$2:$G$500,"hardware_failure")+COUNTIFS(Causal_Event_Ledger!$A$2:$A$500,">="&"2016-01-01",Causal_Event_Ledger!$A$2:$A$500,"<="&"2016-12-31",Causal_Event_Ledger!$H$2:$H$500,"hardware_failure") | I2: =COUNTIFS(Causal_Event_Ledger!$A$2:$A$500,">="&"2016-01-01",Causal_Event_Ledger!$A$2:$A$500,"<="&"2016-12-31",Causal_Event_Ledger!$G$2:$G$500,"software_failure")+COUNTIFS(Causal_Event_Ledger!$A$2:$A$500,">="&"2016-01-01",Causal_Event_Ledger!$A$2:$A$500,"<="&"2016-12-31",Causal_Event_Ledger!$H$2:$H$500,"software_failure") | J2: =COUNTIFS(Causal_Event_Ledger!$A$2:$A$500,">="&"2016-01-01",Causal_Event_Ledger!$A$2:$A$500,"<="&"2016-12-31",Causal_Event_Ledger!$G$2:$G$500,"gnss_jamming")+COUNTIFS(Causal_Event_Ledger!$A$2:$A$500,">="&"2016-01-01",Causal_Event_Ledger!$A$2:$A$500,"<="&"2016-12-31",Causal_Event_Ledger!$H$2:$H$500,"gnss_jamming") | K2: =COUNTIFS(Causal_Event_Ledger!$A$2:$A$500,">="&"2016-01-01",Causal_Event_Ledger!$A$2:$A$500,"<="&"2016-12-31",Causal_Event_Ledger!$G$2:$G$500,"gnss_spoofing")+COUNTIFS(Causal_Event_Ledger!$A$2:$A$500,">="&"2016-01-01",Causal_Event_Ledger!$A$2:$A$500,"<="&"2016-12-31",Causal_Event_Ledger!$H$2:$H$500,"gnss_spoofing") | L2: =COUNTIFS(Causal_Event_Ledger!$A$2:$A$500,">="&"2016-01-01",Causal_Event_Ledger!$A$2:$A$500,"<="&"2016-12-31",Causal_Event_Ledger!$G$2:$G$500,"unknown_investigation")+COUNTIFS(Causal_Event_Ledger!$A$2:$A$500,">="&"2016-01-01",Causal_Event_Ledger!$A$2:$A$500,"<="&"2016-12-31",Causal_Event_Ledger!$H$2:$H$500,"unknown_investigation") | M2: =COUNTIFS(Causal_Event_Ledger!$A$2:$A$500,">="&"2016-01-01",Causal_Event_Ledger!$A$2:$A$500,"<="&"2016-12-31")
A3: 2017 | B3: =COUNTIFS(Causal_Event_Ledger!$A$2:$A$500,">="&"2017-01-01",Causal_Event_Ledger!$A$2:$A$500,"<="&"2017-12-31",Causal_Event_Ledger!$G$2:$G$500,"comms_failure")+COUNTIFS(Causal_Event_Ledger!$A$2:$A$500,">="&"2017-01-01",Causal_Event_Ledger!$A$2:$A$500,"<="&"2017-12-31",Causal_Event_Ledger!$H$2:$H$500,"comms_failure") | C3: =COUNTIFS(Causal_Event_Ledger!$A$2:$A$500,">="&"2017-01-01",Causal_Event_Ledger!$A$2:$A$500,"<="&"2017-12-31",Causal_Event_Ledger!$G$2:$G$500,"surveillance_failure")+COUNTIFS(Causal_Event_Ledger!$A$2:$A$500,">="&"2017-01-01",Causal_Event_Ledger!$A$2:$A$500,"<="&"2017-12-31",Causal_Event_Ledger!$H$2:$H$500,"surveillance_failure") | D3: =COUNTIFS(Causal_Event_Ledger!$A$2:$A$500,">="&"2017-01-01",Causal_Event_Ledger!$A$2:$A$500,"<="&"2017-12-31",Causal_Event_Ledger!$G$2:$G$500,"flight_data_processing")+COUNTIFS(Causal_Event_Ledger!$A$2:$A$500,">="&"2017-01-01",Causal_Event_Ledger!$A$2:$A$500,"<="&"2017-12-31",Causal_Event_Ledger!$H$2:$H$500,"flight_data_processing") | E3: =COUNTIFS(Causal_Event_Ledger!$A$2:$A$500,">="&"2017-01-01",Causal_Event_Ledger!$A$2:$A$500,"<="&"2017-12-31",Causal_Event_Ledger!$G$2:$G$500,"datalink_cpdlc")+COUNTIFS(Causal_Event_Ledger!$A$2:$A$500,">="&"2017-01-01",Causal_Event_Ledger!$A$2:$A$500,"<="&"2017-12-31",Causal_Event_Ledger!$H$2:$H$500,"datalink_cpdlc") | F3: =COUNTIFS(Causal_Event_Ledger!$A$2:$A$500,">="&"2017-01-01",Causal_Event_Ledger!$A$2:$A$500,"<="&"2017-12-31",Causal_Event_Ledger!$G$2:$G$500,"network_connectivity")+COUNTIFS(Causal_Event_Ledger!$A$2:$A$500,">="&"2017-01-01",Causal_Event_Ledger!$A$2:$A$500,"<="&"2017-12-31",Causal_Event_Ledger!$H$2:$H$500,"network_connectivity") | G3: =COUNTIFS(Causal_Event_Ledger!$A$2:$A$500,">="&"2017-01-01",Causal_Event_Ledger!$A$2:$A$500,"<="&"2017-12-31",Causal_Event_Ledger!$G$2:$G$500,"power_failure")+COUNTIFS(Causal_Event_Ledger!$A$2:$A$500,">="&"2017-01-01",Causal_Event_Ledger!$A$2:$A$500,"<="&"2017-12-31",Causal_Event_Ledger!$H$2:$H$500,"power_failure") | H3: =COUNTIFS(Causal_Event_Ledger!$A$2:$A$500,">="&"2017-01-01",Causal_Event_Ledger!$A$2:$A$500,"<="&"2017-12-31",Causal_Event_Ledger!$G$2:$G$500,"hardware_failure")+COUNTIFS(Causal_Event_Ledger!$A$2:$A$500,">="&"2017-01-01",Causal_Event_Ledger!$A$2:$A$500,"<="&"2017-12-31",Causal_Event_Ledger!$H$2:$H$500,"hardware_failure") | I3: =COUNTIFS(Causal_Event_Ledger!$A$2:$A$500,">="&"2017-01-01",Causal_Event_Ledger!$A$2:$A$500,"<="&"2017-12-31",Causal_Event_Ledger!$G$2:$G$500,"software_failure")+COUNTIFS(Causal_Event_Ledger!$A$2:$A$500,">="&"2017-01-01",Causal_Event_Ledger!$A$2:$A$500,"<="&"2017-12-31",Causal_Event_Ledger!$H$2:$H$500,"software_failure") | J3: =COUNTIFS(Causal_Event_Ledger!$A$2:$A$500,">="&"2017-01-01",Causal_Event_Ledger!$A$2:$A$500,"<="&"2017-12-31",Causal_Event_Ledger!$G$2:$G$500,"gnss_jamming")+COUNTIFS(Causal_Event_Ledger!$A$2:$A$500,">="&"2017-01-01",Causal_Event_Ledger!$A$2:$A$500,"<="&"2017-12-31",Causal_Event_Ledger!$H$2:$H$500,"gnss_jamming") | K3: =COUNTIFS(Causal_Event_Ledger!$A$2:$A$500,">="&"2017-01-01",Causal_Event_Ledger!$A$2:$A$500,"<="&"2017-12-31",Causal_Event_Ledger!$G$2:$G$500,"gnss_spoofing")+COUNTIFS(Causal_Event_Ledger!$A$2:$A$500,">="&"2017-01-01",Causal_Event_Ledger!$A$2:$A$500,"<="&"2017-12-31",Causal_Event_Ledger!$H$2:$H$500,"gnss_spoofing") | L3: =COUNTIFS(Causal_Event_Ledger!$A$2:$A$500,">="&"2017-01-01",Causal_Event_Ledger!$A$2:$A$500,"<="&"2017-12-31",Causal_Event_Ledger!$G$2:$G$500,"unknown_investigation")+COUNTIFS(Causal_Event_Ledger!$A$2:$A$500,">="&"2017-01-01",Causal_Event_Ledger!$A$2:$A$500,"<="&"2017-12-31",Causal_Event_Ledger!$H$2:$H$500,"unknown_investigation") | M3: =COUNTIFS(Causal_Event_Ledger!$A$2:$A$500,">="&"2017-01-01",Causal_Event_Ledger!$A$2:$A$500,"<="&"2017-12-31")
A4: 2018 | B4: =COUNTIFS(Causal_Event_Ledger!$A$2:$A$500,">="&"2018-01-01",Causal_Event_Ledger!$A$2:$A$500,"<="&"2018-12-31",Causal_Event_Ledger!$G$2:$G$500,"comms_failure")+COUNTIFS(Causal_Event_Ledger!$A$2:$A$500,">="&"2018-01-01",Causal_Event_Ledger!$A$2:$A$500,"<="&"2018-12-31",Causal_Event_Ledger!$H$2:$H$500,"comms_failure") | C4: =COUNTIFS(Causal_Event_Ledger!$A$2:$A$500,">="&"2018-01-01",Causal_Event_Ledger!$A$2:$A$500,"<="&"2018-12-31",Causal_Event_Ledger!$G$2:$G$500,"surveillance_failure")+COUNTIFS(Causal_Event_Ledger!$A$2:$A$500,">="&"2018-01-01",Causal_Event_Ledger!$A$2:$A$500,"<="&"2018-12-31",Causal_Event_Ledger!$H$2:$H$500,"surveillance_failure") | D4: =COUNTIFS(Causal_Event_Ledger!$A$2:$A$500,">="&"2018-01-01",Causal_Event_Ledger!$A$2:$A$500,"<="&"2018-12-31",Causal_Event_Ledger!$G$2:$G$500,"flight_data_processing")+COUNTIFS(Causal_Event_Ledger!$A$2:$A$500,">="&"2018-01-01",Causal_Event_Ledger!$A$2:$A$500,"<="&"2018-12-31",Causal_Event_Ledger!$H$2:$H$500,"flight_data_processing") | E4: =COUNTIFS(Causal_Event_Ledger!$A$2:$A$500,">="&"2018-01-01",Causal_Event_Ledger!$A$2:$A$500,"<="&"2018-12-31",Causal_Event_Ledger!$G$2:$G$500,"datalink_cpdlc")+COUNTIFS(Causal_Event_Ledger!$A$2:$A$500,">="&"2018-01-01",Causal_Event_Ledger!$A$2:$A$500,"<="&"2018-12-31",Causal_Event_Ledger!$H$2:$H$500,"datalink_cpdlc") | F4: =COUNTIFS(Causal_Event_Ledger!$A$2:$A$500,">="&"2018-01-01",Causal_Event_Ledger!$A$2:$A$500,"<="&"2018-12-31",Causal_Event_Ledger!$G$2:$G$500,"network_connectivity")+COUNTIFS(Causal_Event_Ledger!$A$2:$A$500,">="&"2018-01-01",Causal_Event_Ledger!$A$2:$A$500,"<="&"2018-12-31",Causal_Event_Ledger!$H$2:$H$500,"network_connectivity") | G4: =COUNTIFS(Causal_Event_Ledger!$A$2:$A$500,">="&"2018-01-01",Causal_Event_Ledger!$A$2:$A$500,"<="&"2018-12-31",Causal_Event_Ledger!$G$2:$G$500,"power_failure")+COUNTIFS(Causal_Event_Ledger!$A$2:$A$500,">="&"2018-01-01",Causal_Event_Ledger!$A$2:$A$500,"<="&"2018-12-31",Causal_Event_Ledger!$H$2:$H$500,"power_failure") | H4: =COUNTIFS(Causal_Event_Ledger!$A$2:$A$500,">="&"2018-01-01",Causal_Event_Ledger!$A$2:$A$500,"<="&"2018-12-31",Causal_Event_Ledger!$G$2:$G$500,"hardware_failure")+COUNTIFS(Causal_Event_Ledger!$A$2:$A$500,">="&"2018-01-01",Causal_Event_Ledger!$A$2:$A$500,"<="&"2018-12-31",Causal_Event_Ledger!$H$2:$H$500,"hardware_failure") | I4: =COUNTIFS(Causal_Event_Ledger!$A$2:$A$500,">="&"2018-01-01",Causal_Event_Ledger!$A$2:$A$500,"<="&"2018-12-31",Causal_Event_Ledger!$G$2:$G$500,"software_failure")+COUNTIFS(Causal_Event_Ledger!$A$2:$A$500,">="&"2018-01-01",Causal_Event_Ledger!$A$2:$A$500,"<="&"2018-12-31",Causal_Event_Ledger!$H$2:$H$500,"software_failure") | J4: =COUNTIFS(Causal_Event_Ledger!$A$2:$A$500,">="&"2018-01-01",Causal_Event_Ledger!$A$2:$A$500,"<="&"2018-12-31",Causal_Event_Ledger!$G$2:$G$500,"gnss_jamming")+COUNTIFS(Causal_Event_Ledger!$A$2:$A$500,">="&"2018-01-01",Causal_Event_Ledger!$A$2:$A$500,"<="&"2018-12-31",Causal_Event_Ledger!$H$2:$H$500,"gnss_jamming") | K4: =COUNTIFS(Causal_Event_Ledger!$A$2:$A$500,">="&"2018-01-01",Causal_Event_Ledger!$A$2:$A$500,"<="&"2018-12-31",Causal_Event_Ledger!$G$2:$G$500,"gnss_spoofing")+COUNTIFS(Causal_Event_Ledger!$A$2:$A$500,">="&"2018-01-01",Causal_Event_Ledger!$A$2:$A$500,"<="&"2018-12-31",Causal_Event_Ledger!$H$2:$H$500,"gnss_spoofing") | L4: =COUNTIFS(Causal_Event_Ledger!$A$2:$A$500,">="&"2018-01-01",Causal_Event_Ledger!$A$2:$A$500,"<="&"2018-12-31",Causal_Event_Ledger!$G$2:$G$500,"unknown_investigation")+COUNTIFS(Causal_Event_Ledger!$A$2:$A$500,">="&"2018-01-01",Causal_Event_Ledger!$A$2:$A$500,"<="&"2018-12-31",Causal_Event_Ledger!$H$2:$H$500,"unknown_investigation") | M4: =COUNTIFS(Causal_Event_Ledger!$A$2:$A$500,">="&"2018-01-01",Causal_Event_Ledger!$A$2:$A$500,"<="&"2018-12-31")
A5: 2019 | B5: =COUNTIFS(Causal_Event_Ledger!$A$2:$A$500,">="&"2019-01-01",Causal_Event_Ledger!$A$2:$A$500,"<="&"2019-12-31",Causal_Event_Ledger!$G$2:$G$500,"comms_failure")+COUNTIFS(Causal_Event_Ledger!$A$2:$A$500,">="&"2019-01-01",Causal_Event_Ledger!$A$2:$A$500,"<="&"2019-12-31",Causal_Event_Ledger!$H$2:$H$500,"comms_failure") | C5: =COUNTIFS(Causal_Event_Ledger!$A$2:$A$500,">="&"2019-01-01",Causal_Event_Ledger!$A$2:$A$500,"<="&"2019-12-31",Causal_Event_Ledger!$G$2:$G$500,"surveillance_failure")+COUNTIFS(Causal_Event_Ledger!$A$2:$A$500,">="&"2019-01-01",Causal_Event_Ledger!$A$2:$A$500,"<="&"2019-12-31",Causal_Event_Ledger!$H$2:$H$500,"surveillance_failure") | D5: =COUNTIFS(Causal_Event_Ledger!$A$2:$A$500,">="&"2019-01-01",Causal_Event_Ledger!$A$2:$A$500,"<="&"2019-12-31",Causal_Event_Ledger!$G$2:$G$500,"flight_data_processing")+COUNTIFS(Causal_Event_Ledger!$A$2:$A$500,">="&"2019-01-01",Causal_Event_Ledger!$A$2:$A$500,"<="&"2019-12-31",Causal_Event_Ledger!$H$2:$H$500,"flight_data_processing") | E5: =COUNTIFS(Causal_Event_Ledger!$A$2:$A$500,">="&"2019-01-01",Causal_Event_Ledger!$A$2:$A$500,"<="&"2019-12-31",Causal_Event_Ledger!$G$2:$G$500,"datalink_cpdlc")+COUNTIFS(Causal_Event_Ledger!$A$2:$A$500,">="&"2019-01-01",Causal_Event_Ledger!$A$2:$A$500,"<="&"2019-12-31",Causal_Event_Ledger!$H$2:$H$500,"datalink_cpdlc") | F5: =COUNTIFS(Causal_Event_Ledger!$A$2:$A$500,">="&"2019-01-01",Causal_Event_Ledger!$A$2:$A$500,"<="&"2019-12-31",Causal_Event_Ledger!$G$2:$G$500,"network_connectivity")+COUNTIFS(Causal_Event_Ledger!$A$2:$A$500,">="&"2019-01-01",Causal_Event_Ledger!$A$2:$A$500,"<="&"2019-12-31",Causal_Event_Ledger!$H$2:$H$500,"network_connectivity") | G5: =COUNTIFS(Causal_Event_Ledger!$A$2:$A$500,">="&"2019-01-01",Causal_Event_Ledger!$A$2:$A$500,"<="&"2019-12-31",Causal_Event_Ledger!$G$2:$G$500,"power_failure")+COUNTIFS(Causal_Event_Ledger!$A$2:$A$500,">="&"2019-01-01",Causal_Event_Ledger!$A$2:$A$500,"<="&"2019-12-31",Causal_Event_Ledger!$H$2:$H$500,"power_failure") | H5: =COUNTIFS(Causal_Event_Ledger!$A$2:$A$500,">="&"2019-01-01",Causal_Event_Ledger!$A$2:$A$500,"<="&"2019-12-31",Causal_Event_Ledger!$G$2:$G$500,"hardware_failure")+COUNTIFS(Causal_Event_Ledger!$A$2:$A$500,">="&"2019-01-01",Causal_Event_Ledger!$A$2:$A$500,"<="&"2019-12-31",Causal_Event_Ledger!$H$2:$H$500,"hardware_failure") | I5: =COUNTIFS(Causal_Event_Ledger!$A$2:$A$500,">="&"2019-01-01",Causal_Event_Ledger!$A$2:$A$500,"<="&"2019-12-31",Causal_Event_Ledger!$G$2:$G$500,"software_failure")+COUNTIFS(Causal_Event_Ledger!$A$2:$A$500,">="&"2019-01-01",Causal_Event_Ledger!$A$2:$A$500,"<="&"2019-12-31",Causal_Event_Ledger!$H$2:$H$500,"software_failure") | J5: =COUNTIFS(Causal_Event_Ledger!$A$2:$A$500,">="&"2019-01-01",Causal_Event_Ledger!$A$2:$A$500,"<="&"2019-12-31",Causal_Event_Ledger!$G$2:$G$500,"gnss_jamming")+COUNTIFS(Causal_Event_Ledger!$A$2:$A$500,">="&"2019-01-01",Causal_Event_Ledger!$A$2:$A$500,"<="&"2019-12-31",Causal_Event_Ledger!$H$2:$H$500,"gnss_jamming") | K5: =COUNTIFS(Causal_Event_Ledger!$A$2:$A$500,">="&"2019-01-01",Causal_Event_Ledger!$A$2:$A$500,"<="&"2019-12-31",Causal_Event_Ledger!$G$2:$G$500,"gnss_spoofing")+COUNTIFS(Causal_Event_Ledger!$A$2:$A$500,">="&"2019-01-01",Causal_Event_Ledger!$A$2:$A$500,"<="&"2019-12-31",Causal_Event_Ledger!$H$2:$H$500,"gnss_spoofing") | L5: =COUNTIFS(Causal_Event_Ledger!$A$2:$A$500,">="&"2019-01-01",Causal_Event_Ledger!$A$2:$A$500,"<="&"2019-12-31",Causal_Event_Ledger!$G$2:$G$500,"unknown_investigation")+COUNTIFS(Causal_Event_Ledger!$A$2:$A$500,">="&"2019-01-01",Causal_Event_Ledger!$A$2:$A$500,"<="&"2019-12-31",Causal_Event_Ledger!$H$2:$H$500,"unknown_investigation") | M5: =COUNTIFS(Causal_Event_Ledger!$A$2:$A$500,">="&"2019-01-01",Causal_Event_Ledger!$A$2:$A$500,"<="&"2019-12-31")
A6: 2020 | B6: =COUNTIFS(Causal_Event_Ledger!$A$2:$A$500,">="&"2020-01-01",Causal_Event_Ledger!$A$2:$A$500,"<="&"2020-12-31",Causal_Event_Ledger!$G$2:$G$500,"comms_failure")+COUNTIFS(Causal_Event_Ledger!$A$2:$A$500,">="&"2020-01-01",Causal_Event_Ledger!$A$2:$A$500,"<="&"2020-12-31",Causal_Event_Ledger!$H$2:$H$500,"comms_failure") | C6: =COUNTIFS(Causal_Event_Ledger!$A$2:$A$500,">="&"2020-01-01",Causal_Event_Ledger!$A$2:$A$500,"<="&"2020-12-31",Causal_Event_Ledger!$G$2:$G$500,"surveillance_failure")+COUNTIFS(Causal_Event_Ledger!$A$2:$A$500,">="&"2020-01-01",Causal_Event_Ledger!$A$2:$A$500,"<="&"2020-12-31",Causal_Event_Ledger!$H$2:$H$500,"surveillance_failure") | D6: =COUNTIFS(Causal_Event_Ledger!$A$2:$A$500,">="&"2020-01-01",Causal_Event_Ledger!$A$2:$A$500,"<="&"2020-12-31",Causal_Event_Ledger!$G$2:$G$500,"flight_data_processing")+COUNTIFS(Causal_Event_Ledger!$A$2:$A$500,">="&"2020-01-01",Causal_Event_Ledger!$A$2:$A$500,"<="&"2020-12-31",Causal_Event_Ledger!$H$2:$H$500,"flight_data_processing") | E6: =COUNTIFS(Causal_Event_Ledger!$A$2:$A$500,">="&"2020-01-01",Causal_Event_Ledger!$A$2:$A$500,"<="&"2020-12-31",Causal_Event_Ledger!$G$2:$G$500,"datalink_cpdlc")+COUNTIFS(Causal_Event_Ledger!$A$2:$A$500,">="&"2020-01-01",Causal_Event_Ledger!$A$2:$A$500,"<="&"2020-12-31",Causal_Event_Ledger!$H$2:$H$500,"datalink_cpdlc") | F6: =COUNTIFS(Causal_Event_Ledger!$A$2:$A$500,">="&"2020-01-01",Causal_Event_Ledger!$A$2:$A$500,"<="&"2020-12-31",Causal_Event_Ledger!$G$2:$G$500,"network_connectivity")+COUNTIFS(Causal_Event_Ledger!$A$2:$A$500,">="&"2020-01-01",Causal_Event_Ledger!$A$2:$A$500,"<="&"2020-12-31",Causal_Event_Ledger!$H$2:$H$500,"network_connectivity") | G6: =COUNTIFS(Causal_Event_Ledger!$A$2:$A$500,">="&"2020-01-01",Causal_Event_Ledger!$A$2:$A$500,"<="&"2020-12-31",Causal_Event_Ledger!$G$2:$G$500,"power_failure")+COUNTIFS(Causal_Event_Ledger!$A$2:$A$500,">="&"2020-01-01",Causal_Event_Ledger!$A$2:$A$500,"<="&"2020-12-31",Causal_Event_Ledger!$H$2:$H$500,"power_failure") | H6: =COUNTIFS(Causal_Event_Ledger!$A$2:$A$500,">="&"2020-01-01",Causal_Event_Ledger!$A$2:$A$500,"<="&"2020-12-31",Causal_Event_Ledger!$G$2:$G$500,"hardware_failure")+COUNTIFS(Causal_Event_Ledger!$A$2:$A$500,">="&"2020-01-01",Causal_Event_Ledger!$A$2:$A$500,"<="&"2020-12-31",Causal_Event_Ledger!$H$2:$H$500,"hardware_failure") | I6: =COUNTIFS(Causal_Event_Ledger!$A$2:$A$500,">="&"2020-01-01",Causal_Event_Ledger!$A$2:$A$500,"<="&"2020-12-31",Causal_Event_Ledger!$G$2:$G$500,"software_failure")+COUNTIFS(Causal_Event_Ledger!$A$2:$A$500,">="&"2020-01-01",Causal_Event_Ledger!$A$2:$A$500,"<="&"2020-12-31",Causal_Event_Ledger!$H$2:$H$500,"software_failure") | J6: =COUNTIFS(Causal_Event_Ledger!$A$2:$A$500,">="&"2020-01-01",Causal_Event_Ledger!$A$2:$A$500,"<="&"2020-12-31",Causal_Event_Ledger!$G$2:$G$500,"gnss_jamming")+COUNTIFS(Causal_Event_Ledger!$A$2:$A$500,">="&"2020-01-01",Causal_Event_Ledger!$A$2:$A$500,"<="&"2020-12-31",Causal_Event_Ledger!$H$2:$H$500,"gnss_jamming") | K6: =COUNTIFS(Causal_Event_Ledger!$A$2:$A$500,">="&"2020-01-01",Causal_Event_Ledger!$A$2:$A$500,"<="&"2020-12-31",Causal_Event_Ledger!$G$2:$G$500,"gnss_spoofing")+COUNTIFS(Causal_Event_Ledger!$A$2:$A$500,">="&"2020-01-01",Causal_Event_Ledger!$A$2:$A$500,"<="&"2020-12-31",Causal_Event_Ledger!$H$2:$H$500,"gnss_spoofing") | L6: =COUNTIFS(Causal_Event_Ledger!$A$2:$A$500,">="&"2020-01-01",Causal_Event_Ledger!$A$2:$A$500,"<="&"2020-12-31",Causal_Event_Ledger!$G$2:$G$500,"unknown_investigation")+COUNTIFS(Causal_Event_Ledger!$A$2:$A$500,">="&"2020-01-01",Causal_Event_Ledger!$A$2:$A$500,"<="&"2020-12-31",Causal_Event_Ledger!$H$2:$H$500,"unknown_investigation") | M6: =COUNTIFS(Causal_Event_Ledger!$A$2:$A$500,">="&"2020-01-01",Causal_Event_Ledger!$A$2:$A$500,"<="&"2020-12-31")
A7: 2021 | B7: =COUNTIFS(Causal_Event_Ledger!$A$2:$A$500,">="&"2021-01-01",Causal_Event_Ledger!$A$2:$A$500,"<="&"2021-12-31",Causal_Event_Ledger!$G$2:$G$500,"comms_failure")+COUNTIFS(Causal_Event_Ledger!$A$2:$A$500,">="&"2021-01-01",Causal_Event_Ledger!$A$2:$A$500,"<="&"2021-12-31",Causal_Event_Ledger!$H$2:$H$500,"comms_failure") | C7: =COUNTIFS(Causal_Event_Ledger!$A$2:$A$500,">="&"2021-01-01",Causal_Event_Ledger!$A$2:$A$500,"<="&"2021-12-31",Causal_Event_Ledger!$G$2:$G$500,"surveillance_failure")+COUNTIFS(Causal_Event_Ledger!$A$2:$A$500,">="&"2021-01-01",Causal_Event_Ledger!$A$2:$A$500,"<="&"2021-12-31",Causal_Event_Ledger!$H$2:$H$500,"surveillance_failure") | D7: =COUNTIFS(Causal_Event_Ledger!$A$2:$A$500,">="&"2021-01-01",Causal_Event_Ledger!$A$2:$A$500,"<="&"2021-12-31",Causal_Event_Ledger!$G$2:$G$500,"flight_data_processing")+COUNTIFS(Causal_Event_Ledger!$A$2:$A$500,">="&"2021-01-01",Causal_Event_Ledger!$A$2:$A$500,"<="&"2021-12-31",Causal_Event_Ledger!$H$2:$H$500,"flight_data_processing") | E7: =COUNTIFS(Causal_Event_Ledger!$A$2:$A$500,">="&"2021-01-01",Causal_Event_Ledger!$A$2:$A$500,"<="&"2021-12-31",Causal_Event_Ledger!$G$2:$G$500,"datalink_cpdlc")+COUNTIFS(Causal_Event_Ledger!$A$2:$A$500,">="&"2021-01-01",Causal_Event_Ledger!$A$2:$A$500,"<="&"2021-12-31",Causal_Event_Ledger!$H$2:$H$500,"datalink_cpdlc") | F7: =COUNTIFS(Causal_Event_Ledger!$A$2:$A$500,">="&"2021-01-01",Causal_Event_Ledger!$A$2:$A$500,"<="&"2021-12-31",Causal_Event_Ledger!$G$2:$G$500,"network_connectivity")+COUNTIFS(Causal_Event_Ledger!$A$2:$A$500,">="&"2021-01-01",Causal_Event_Ledger!$A$2:$A$500,"<="&"2021-12-31",Causal_Event_Ledger!$H$2:$H$500,"network_connectivity") | G7: =COUNTIFS(Causal_Event_Ledger!$A$2:$A$500,">="&"2021-01-01",Causal_Event_Ledger!$A$2:$A$500,"<="&"2021-12-31",Causal_Event_Ledger!$G$2:$G$500,"power_failure")+COUNTIFS(Causal_Event_Ledger!$A$2:$A$500,">="&"2021-01-01",Causal_Event_Ledger!$A$2:$A$500,"<="&"2021-12-31",Causal_Event_Ledger!$H$2:$H$500,"power_failure") | H7: =COUNTIFS(Causal_Event_Ledger!$A$2:$A$500,">="&"2021-01-01",Causal_Event_Ledger!$A$2:$A$500,"<="&"2021-12-31",Causal_Event_Ledger!$G$2:$G$500,"hardware_failure")+COUNTIFS(Causal_Event_Ledger!$A$2:$A$500,">="&"2021-01-01",Causal_Event_Ledger!$A$2:$A$500,"<="&"2021-12-31",Causal_Event_Ledger!$H$2:$H$500,"hardware_failure") | I7: =COUNTIFS(Causal_Event_Ledger!$A$2:$A$500,">="&"2021-01-01",Causal_Event_Ledger!$A$2:$A$500,"<="&"2021-12-31",Causal_Event_Ledger!$G$2:$G$500,"software_failure")+COUNTIFS(Causal_Event_Ledger!$A$2:$A$500,">="&"2021-01-01",Causal_Event_Ledger!$A$2:$A$500,"<="&"2021-12-31",Causal_Event_Ledger!$H$2:$H$500,"software_failure") | J7: =COUNTIFS(Causal_Event_Ledger!$A$2:$A$500,">="&"2021-01-01",Causal_Event_Ledger!$A$2:$A$500,"<="&"2021-12-31",Causal_Event_Ledger!$G$2:$G$500,"gnss_jamming")+COUNTIFS(Causal_Event_Ledger!$A$2:$A$500,">="&"2021-01-01",Causal_Event_Ledger!$A$2:$A$500,"<="&"2021-12-31",Causal_Event_Ledger!$H$2:$H$500,"gnss_jamming") | K7: =COUNTIFS(Causal_Event_Ledger!$A$2:$A$500,">="&"2021-01-01",Causal_Event_Ledger!$A$2:$A$500,"<="&"2021-12-31",Causal_Event_Ledger!$G$2:$G$500,"gnss_spoofing")+COUNTIFS(Causal_Event_Ledger!$A$2:$A$500,">="&"2021-01-01",Causal_Event_Ledger!$A$2:$A$500,"<="&"2021-12-31",Causal_Event_Ledger!$H$2:$H$500,"gnss_spoofing") | L7: =COUNTIFS(Causal_Event_Ledger!$A$2:$A$500,">="&"2021-01-01",Causal_Event_Ledger!$A$2:$A$500,"<="&"2021-12-31",Causal_Event_Ledger!$G$2:$G$500,"unknown_investigation")+COUNTIFS(Causal_Event_Ledger!$A$2:$A$500,">="&"2021-01-01",Causal_Event_Ledger!$A$2:$A$500,"<="&"2021-12-31",Causal_Event_Ledger!$H$2:$H$500,"unknown_investigation") | M7: =COUNTIFS(Causal_Event_Ledger!$A$2:$A$500,">="&"2021-01-01",Causal_Event_Ledger!$A$2:$A$500,"<="&"2021-12-31")
A8: 2022 | B8: =COUNTIFS(Causal_Event_Ledger!$A$2:$A$500,">="&"2022-01-01",Causal_Event_Ledger!$A$2:$A$500,"<="&"2022-12-31",Causal_Event_Ledger!$G$2:$G$500,"comms_failure")+COUNTIFS(Causal_Event_Ledger!$A$2:$A$500,">="&"2022-01-01",Causal_Event_Ledger!$A$2:$A$500,"<="&"2022-12-31",Causal_Event_Ledger!$H$2:$H$500,"comms_failure") | C8: =COUNTIFS(Causal_Event_Ledger!$A$2:$A$500,">="&"2022-01-01",Causal_Event_Ledger!$A$2:$A$500,"<="&"2022-12-31",Causal_Event_Ledger!$G$2:$G$500,"surveillance_failure")+COUNTIFS(Causal_Event_Ledger!$A$2:$A$500,">="&"2022-01-01",Causal_Event_Ledger!$A$2:$A$500,"<="&"2022-12-31",Causal_Event_Ledger!$H$2:$H$500,"surveillance_failure") | D8: =COUNTIFS(Causal_Event_Ledger!$A$2:$A$500,">="&"2022-01-01",Causal_Event_Ledger!$A$2:$A$500,"<="&"2022-12-31",Causal_Event_Ledger!$G$2:$G$500,"flight_data_processing")+COUNTIFS(Causal_Event_Ledger!$A$2:$A$500,">="&"2022-01-01",Causal_Event_Ledger!$A$2:$A$500,"<="&"2022-12-31",Causal_Event_Ledger!$H$2:$H$500,"flight_data_processing") | E8: =COUNTIFS(Causal_Event_Ledger!$A$2:$A$500,">="&"2022-01-01",Causal_Event_Ledger!$A$2:$A$500,"<="&"2022-12-31",Causal_Event_Ledger!$G$2:$G$500,"datalink_cpdlc")+COUNTIFS(Causal_Event_Ledger!$A$2:$A$500,">="&"2022-01-01",Causal_Event_Ledger!$A$2:$A$500,"<="&"2022-12-31",Causal_Event_Ledger!$H$2:$H$500,"datalink_cpdlc") | F8: =COUNTIFS(Causal_Event_Ledger!$A$2:$A$500,">="&"2022-01-01",Causal_Event_Ledger!$A$2:$A$500,"<="&"2022-12-31",Causal_Event_Ledger!$G$2:$G$500,"network_connectivity")+COUNTIFS(Causal_Event_Ledger!$A$2:$A$500,">="&"2022-01-01",Causal_Event_Ledger!$A$2:$A$500,"<="&"2022-12-31",Causal_Event_Ledger!$H$2:$H$500,"network_connectivity") | G8: =COUNTIFS(Causal_Event_Ledger!$A$2:$A$500,">="&"2022-01-01",Causal_Event_Ledger!$A$2:$A$500,"<="&"2022-12-31",Causal_Event_Ledger!$G$2:$G$500,"power_failure")+COUNTIFS(Causal_Event_Ledger!$A$2:$A$500,">="&"2022-01-01",Causal_Event_Ledger!$A$2:$A$500,"<="&"2022-12-31",Causal_Event_Ledger!$H$2:$H$500,"power_failure") | H8: =COUNTIFS(Causal_Event_Ledger!$A$2:$A$500,">="&"2022-01-01",Causal_Event_Ledger!$A$2:$A$500,"<="&"2022-12-31",Causal_Event_Ledger!$G$2:$G$500,"hardware_failure")+COUNTIFS(Causal_Event_Ledger!$A$2:$A$500,">="&"2022-01-01",Causal_Event_Ledger!$A$2:$A$500,"<="&"2022-12-31",Causal_Event_Ledger!$H$2:$H$500,"hardware_failure") | I8: =COUNTIFS(Causal_Event_Ledger!$A$2:$A$500,">="&"2022-01-01",Causal_Event_Ledger!$A$2:$A$500,"<="&"2022-12-31",Causal_Event_Ledger!$G$2:$G$500,"software_failure")+COUNTIFS(Causal_Event_Ledger!$A$2:$A$500,">="&"2022-01-01",Causal_Event_Ledger!$A$2:$A$500,"<="&"2022-12-31",Causal_Event_Ledger!$H$2:$H$500,"software_failure") | J8: =COUNTIFS(Causal_Event_Ledger!$A$2:$A$500,">="&"2022-01-01",Causal_Event_Ledger!$A$2:$A$500,"<="&"2022-12-31",Causal_Event_Ledger!$G$2:$G$500,"gnss_jamming")+COUNTIFS(Causal_Event_Ledger!$A$2:$A$500,">="&"2022-01-01",Causal_Event_Ledger!$A$2:$A$500,"<="&"2022-12-31",Causal_Event_Ledger!$H$2:$H$500,"gnss_jamming") | K8: =COUNTIFS(Causal_Event_Ledger!$A$2:$A$500,">="&"2022-01-01",Causal_Event_Ledger!$A$2:$A$500,"<="&"2022-12-31",Causal_Event_Ledger!$G$2:$G$500,"gnss_spoofing")+COUNTIFS(Causal_Event_Ledger!$A$2:$A$500,">="&"2022-01-01",Causal_Event_Ledger!$A$2:$A$500,"<="&"2022-12-31",Causal_Event_Ledger!$H$2:$H$500,"gnss_spoofing") | L8: =COUNTIFS(Causal_Event_Ledger!$A$2:$A$500,">="&"2022-01-01",Causal_Event_Ledger!$A$2:$A$500,"<="&"2022-12-31",Causal_Event_Ledger!$G$2:$G$500,"unknown_investigation")+COUNTIFS(Causal_Event_Ledger!$A$2:$A$500,">="&"2022-01-01",Causal_Event_Ledger!$A$2:$A$500,"<="&"2022-12-31",Causal_Event_Ledger!$H$2:$H$500,"unknown_investigation") | M8: =COUNTIFS(Causal_Event_Ledger!$A$2:$A$500,">="&"2022-01-01",Causal_Event_Ledger!$A$2:$A$500,"<="&"2022-12-31")
